INFO:django.utils.autoreload:C:\Users\axiax\Desktop\hakaton\users\views.py changed, reloading.
WARNING:django.request:Not Found: /
ERROR:django.request:Internal Server Error: /register/
Traceback (most recent call last):
  File "C:\Users\axiax\AppData\Local\Programs\Python\Python38\lib\site-packages\django\urls\base.py", line 71, in reverse
    extra, resolver = resolver.namespace_dict[ns]
KeyError: 'site_content'

During handling of the above exception, another exception occurred:

Traceback (most recent call last):
  File "C:\Users\axiax\AppData\Local\Programs\Python\Python38\lib\site-packages\django\core\handlers\exception.py", line 47, in inner
    response = get_response(request)
  File "C:\Users\axiax\AppData\Local\Programs\Python\Python38\lib\site-packages\django\core\handlers\base.py", line 181, in _get_response
    response = wrapped_callback(request, *callback_args, **callback_kwargs)
  File "C:\Users\axiax\AppData\Local\Programs\Python\Python38\lib\site-packages\django\views\generic\base.py", line 70, in view
    return self.dispatch(request, *args, **kwargs)
  File "C:\Users\axiax\AppData\Local\Programs\Python\Python38\lib\site-packages\django\views\generic\base.py", line 98, in dispatch
    return handler(request, *args, **kwargs)
  File "C:\Users\axiax\Desktop\hakaton\users\views.py", line 35, in get
    return redirect('site_content:result')
  File "C:\Users\axiax\AppData\Local\Programs\Python\Python38\lib\site-packages\django\shortcuts.py", line 41, in redirect
    return redirect_class(resolve_url(to, *args, **kwargs))
  File "C:\Users\axiax\AppData\Local\Programs\Python\Python38\lib\site-packages\django\shortcuts.py", line 130, in resolve_url
    return reverse(to, args=args, kwargs=kwargs)
  File "C:\Users\axiax\AppData\Local\Programs\Python\Python38\lib\site-packages\django\urls\base.py", line 82, in reverse
    raise NoReverseMatch("%s is not a registered namespace" % key)
django.urls.exceptions.NoReverseMatch: 'site_content' is not a registered namespace
INFO:django.utils.autoreload:C:\Users\axiax\Desktop\hakaton\users\forms.py changed, reloading.
INFO:django.utils.autoreload:C:\Users\axiax\Desktop\hakaton\users\forms.py changed, reloading.
INFO:django.utils.autoreload:C:\Users\axiax\Desktop\hakaton\users\views.py changed, reloading.
INFO:django.utils.autoreload:C:\Users\axiax\Desktop\hakaton\users\views.py changed, reloading.
INFO:django.utils.autoreload:C:\Users\axiax\Desktop\hakaton\hakaton\settings.py changed, reloading.
INFO:django.utils.autoreload:C:\Users\axiax\Desktop\hakaton\hakaton\urls.py changed, reloading.
ERROR:django.request:Internal Server Error: /
Traceback (most recent call last):
  File "C:\Users\axiax\AppData\Local\Programs\Python\Python38\lib\site-packages\django\core\handlers\exception.py", line 47, in inner
    response = get_response(request)
  File "C:\Users\axiax\AppData\Local\Programs\Python\Python38\lib\site-packages\django\core\handlers\base.py", line 204, in _get_response
    response = response.render()
  File "C:\Users\axiax\AppData\Local\Programs\Python\Python38\lib\site-packages\django\template\response.py", line 105, in render
    self.content = self.rendered_content
  File "C:\Users\axiax\AppData\Local\Programs\Python\Python38\lib\site-packages\django\template\response.py", line 81, in rendered_content
    template = self.resolve_template(self.template_name)
  File "C:\Users\axiax\AppData\Local\Programs\Python\Python38\lib\site-packages\django\template\response.py", line 63, in resolve_template
    return select_template(template, using=self.using)
  File "C:\Users\axiax\AppData\Local\Programs\Python\Python38\lib\site-packages\django\template\loader.py", line 47, in select_template
    raise TemplateDoesNotExist(', '.join(template_name_list), chain=chain)
django.template.exceptions.TemplateDoesNotExist: users/registration.html
ERROR:django.request:Internal Server Error: /
Traceback (most recent call last):
  File "C:\Users\axiax\AppData\Local\Programs\Python\Python38\lib\site-packages\django\core\handlers\exception.py", line 47, in inner
    response = get_response(request)
  File "C:\Users\axiax\AppData\Local\Programs\Python\Python38\lib\site-packages\django\core\handlers\base.py", line 204, in _get_response
    response = response.render()
  File "C:\Users\axiax\AppData\Local\Programs\Python\Python38\lib\site-packages\django\template\response.py", line 105, in render
    self.content = self.rendered_content
  File "C:\Users\axiax\AppData\Local\Programs\Python\Python38\lib\site-packages\django\template\response.py", line 81, in rendered_content
    template = self.resolve_template(self.template_name)
  File "C:\Users\axiax\AppData\Local\Programs\Python\Python38\lib\site-packages\django\template\response.py", line 63, in resolve_template
    return select_template(template, using=self.using)
  File "C:\Users\axiax\AppData\Local\Programs\Python\Python38\lib\site-packages\django\template\loader.py", line 47, in select_template
    raise TemplateDoesNotExist(', '.join(template_name_list), chain=chain)
django.template.exceptions.TemplateDoesNotExist: users/registration.html
WARNING:django.request:Not Found: /favicon.ico
ERROR:django.request:Internal Server Error: /
Traceback (most recent call last):
  File "C:\Users\axiax\AppData\Local\Programs\Python\Python38\lib\site-packages\django\core\handlers\exception.py", line 47, in inner
    response = get_response(request)
  File "C:\Users\axiax\AppData\Local\Programs\Python\Python38\lib\site-packages\django\core\handlers\base.py", line 204, in _get_response
    response = response.render()
  File "C:\Users\axiax\AppData\Local\Programs\Python\Python38\lib\site-packages\django\template\response.py", line 105, in render
    self.content = self.rendered_content
  File "C:\Users\axiax\AppData\Local\Programs\Python\Python38\lib\site-packages\django\template\response.py", line 81, in rendered_content
    template = self.resolve_template(self.template_name)
  File "C:\Users\axiax\AppData\Local\Programs\Python\Python38\lib\site-packages\django\template\response.py", line 63, in resolve_template
    return select_template(template, using=self.using)
  File "C:\Users\axiax\AppData\Local\Programs\Python\Python38\lib\site-packages\django\template\loader.py", line 47, in select_template
    raise TemplateDoesNotExist(', '.join(template_name_list), chain=chain)
django.template.exceptions.TemplateDoesNotExist: users/registration.html
WARNING:django.request:Not Found: /favicon.ico
INFO:django.utils.autoreload:C:\Users\axiax\Desktop\hakaton\users\views.py changed, reloading.
ERROR:django.request:Internal Server Error: /
Traceback (most recent call last):
  File "C:\Users\axiax\AppData\Local\Programs\Python\Python38\lib\site-packages\django\core\handlers\exception.py", line 47, in inner
    response = get_response(request)
  File "C:\Users\axiax\AppData\Local\Programs\Python\Python38\lib\site-packages\django\core\handlers\base.py", line 204, in _get_response
    response = response.render()
  File "C:\Users\axiax\AppData\Local\Programs\Python\Python38\lib\site-packages\django\template\response.py", line 105, in render
    self.content = self.rendered_content
  File "C:\Users\axiax\AppData\Local\Programs\Python\Python38\lib\site-packages\django\template\response.py", line 81, in rendered_content
    template = self.resolve_template(self.template_name)
  File "C:\Users\axiax\AppData\Local\Programs\Python\Python38\lib\site-packages\django\template\response.py", line 63, in resolve_template
    return select_template(template, using=self.using)
  File "C:\Users\axiax\AppData\Local\Programs\Python\Python38\lib\site-packages\django\template\loader.py", line 47, in select_template
    raise TemplateDoesNotExist(', '.join(template_name_list), chain=chain)
django.template.exceptions.TemplateDoesNotExist: registration.html
INFO:django.utils.autoreload:C:\Users\axiax\Desktop\hakaton\users\views.py changed, reloading.
INFO:django.utils.autoreload:C:\Users\axiax\Desktop\hakaton\templates\index.html changed, reloading.
INFO:django.utils.autoreload:C:\Users\axiax\Desktop\hakaton\templates\index.html changed, reloading.
INFO:django.utils.autoreload:C:\Users\axiax\Desktop\hakaton\templates\index.html changed, reloading.
INFO:django.utils.autoreload:C:\Users\axiax\Desktop\hakaton\templates\index.html changed, reloading.
INFO:django.utils.autoreload:C:\Users\axiax\Desktop\hakaton\templates\index.html changed, reloading.
INFO:django.utils.autoreload:C:\Users\axiax\Desktop\hakaton\templates\index.html changed, reloading.
INFO:django.utils.autoreload:C:\Users\axiax\Desktop\hakaton\templates\index.html changed, reloading.
INFO:django.utils.autoreload:C:\Users\axiax\Desktop\hakaton\templates\index.html changed, reloading.
INFO:django.utils.autoreload:C:\Users\axiax\Desktop\hakaton\users\views.py changed, reloading.
INFO:django.utils.autoreload:C:\Users\axiax\Desktop\hakaton\users\views.py changed, reloading.
INFO:django.utils.autoreload:C:\Users\axiax\Desktop\hakaton\users\views.py changed, reloading.
INFO:django.utils.autoreload:C:\Users\axiax\Desktop\hakaton\templates\index.html changed, reloading.
WARNING:django.security.csrf:Forbidden (CSRF token missing or incorrect.): /
INFO:django.utils.autoreload:C:\Users\axiax\Desktop\hakaton\templates\index.html changed, reloading.
ERROR:django.request:Internal Server Error: /
Traceback (most recent call last):
  File "C:\Users\axiax\AppData\Local\Programs\Python\Python38\lib\site-packages\django\core\handlers\exception.py", line 47, in inner
    response = get_response(request)
  File "C:\Users\axiax\AppData\Local\Programs\Python\Python38\lib\site-packages\django\core\handlers\base.py", line 181, in _get_response
    response = wrapped_callback(request, *callback_args, **callback_kwargs)
  File "C:\Users\axiax\AppData\Local\Programs\Python\Python38\lib\site-packages\django\views\generic\base.py", line 70, in view
    return self.dispatch(request, *args, **kwargs)
  File "C:\Users\axiax\AppData\Local\Programs\Python\Python38\lib\site-packages\django\views\generic\base.py", line 98, in dispatch
    return handler(request, *args, **kwargs)
  File "C:\Users\axiax\AppData\Local\Programs\Python\Python38\lib\site-packages\django\views\generic\edit.py", line 141, in post
    if form.is_valid():
  File "C:\Users\axiax\AppData\Local\Programs\Python\Python38\lib\site-packages\django\forms\forms.py", line 175, in is_valid
    return self.is_bound and not self.errors
  File "C:\Users\axiax\AppData\Local\Programs\Python\Python38\lib\site-packages\django\forms\forms.py", line 170, in errors
    self.full_clean()
  File "C:\Users\axiax\AppData\Local\Programs\Python\Python38\lib\site-packages\django\forms\forms.py", line 372, in full_clean
    self._clean_fields()
  File "C:\Users\axiax\AppData\Local\Programs\Python\Python38\lib\site-packages\django\forms\forms.py", line 393, in _clean_fields
    value = getattr(self, 'clean_%s' % name)()
  File "C:\Users\axiax\Desktop\hakaton\users\forms.py", line 35, in clean_phone
    phone = super().clean_phone()
  File "C:\Users\axiax\Desktop\hakaton\users\forms.py", line 18, in clean_phone
    phone = phone_parser(self.data['phone'])
NameError: name 'phone_parser' is not defined
INFO:django.utils.autoreload:C:\Users\axiax\Desktop\hakaton\users\forms.py changed, reloading.
ERROR:django.request:Internal Server Error: /
Traceback (most recent call last):
  File "C:\Users\axiax\AppData\Local\Programs\Python\Python38\lib\site-packages\django\core\handlers\exception.py", line 47, in inner
    response = get_response(request)
  File "C:\Users\axiax\AppData\Local\Programs\Python\Python38\lib\site-packages\django\core\handlers\base.py", line 181, in _get_response
    response = wrapped_callback(request, *callback_args, **callback_kwargs)
  File "C:\Users\axiax\AppData\Local\Programs\Python\Python38\lib\site-packages\django\views\generic\base.py", line 70, in view
    return self.dispatch(request, *args, **kwargs)
  File "C:\Users\axiax\AppData\Local\Programs\Python\Python38\lib\site-packages\django\views\generic\base.py", line 98, in dispatch
    return handler(request, *args, **kwargs)
  File "C:\Users\axiax\AppData\Local\Programs\Python\Python38\lib\site-packages\django\views\generic\edit.py", line 142, in post
    return self.form_valid(form)
  File "C:\Users\axiax\Desktop\hakaton\users\views.py", line 45, in form_valid
    if User.objects.filter(username=phone, is_password_changed=False).exists():
  File "C:\Users\axiax\AppData\Local\Programs\Python\Python38\lib\site-packages\django\db\models\manager.py", line 85, in manager_method
    return getattr(self.get_queryset(), name)(*args, **kwargs)
  File "C:\Users\axiax\AppData\Local\Programs\Python\Python38\lib\site-packages\django\db\models\query.py", line 941, in filter
    return self._filter_or_exclude(False, args, kwargs)
  File "C:\Users\axiax\AppData\Local\Programs\Python\Python38\lib\site-packages\django\db\models\query.py", line 961, in _filter_or_exclude
    clone._filter_or_exclude_inplace(negate, args, kwargs)
  File "C:\Users\axiax\AppData\Local\Programs\Python\Python38\lib\site-packages\django\db\models\query.py", line 968, in _filter_or_exclude_inplace
    self._query.add_q(Q(*args, **kwargs))
  File "C:\Users\axiax\AppData\Local\Programs\Python\Python38\lib\site-packages\django\db\models\sql\query.py", line 1396, in add_q
    clause, _ = self._add_q(q_object, self.used_aliases)
  File "C:\Users\axiax\AppData\Local\Programs\Python\Python38\lib\site-packages\django\db\models\sql\query.py", line 1415, in _add_q
    child_clause, needed_inner = self.build_filter(
  File "C:\Users\axiax\AppData\Local\Programs\Python\Python38\lib\site-packages\django\db\models\sql\query.py", line 1289, in build_filter
    lookups, parts, reffed_expression = self.solve_lookup_type(arg)
  File "C:\Users\axiax\AppData\Local\Programs\Python\Python38\lib\site-packages\django\db\models\sql\query.py", line 1115, in solve_lookup_type
    _, field, _, lookup_parts = self.names_to_path(lookup_splitted, self.get_meta())
  File "C:\Users\axiax\AppData\Local\Programs\Python\Python38\lib\site-packages\django\db\models\sql\query.py", line 1542, in names_to_path
    raise FieldError("Cannot resolve keyword '%s' into field. "
django.core.exceptions.FieldError: Cannot resolve keyword 'is_password_changed' into field. Choices are: date_joined, email, first_name, groups, id, is_active, is_staff, is_superuser, last_login, last_name, logentry, password, score, user_permissions, username
INFO:django.utils.autoreload:C:\Users\axiax\Desktop\hakaton\users\forms.py changed, reloading.
INFO:django.utils.autoreload:C:\Users\axiax\Desktop\hakaton\users\forms.py changed, reloading.
INFO:django.utils.autoreload:C:\Users\axiax\Desktop\hakaton\templates\index.html changed, reloading.
INFO:django.utils.autoreload:C:\Users\axiax\Desktop\hakaton\hakaton\urls.py changed, reloading.
INFO:django.utils.autoreload:C:\Users\axiax\Desktop\hakaton\users\views.py changed, reloading.
INFO:django.utils.autoreload:C:\Users\axiax\Desktop\hakaton\hakaton\urls.py changed, reloading.
INFO:django.utils.autoreload:C:\Users\axiax\Desktop\hakaton\users\views.py changed, reloading.
INFO:django.utils.autoreload:C:\Users\axiax\Desktop\hakaton\users\views.py changed, reloading.
INFO:django.utils.autoreload:C:\Users\axiax\Desktop\hakaton\users\models.py changed, reloading.
INFO:django.utils.autoreload:C:\Users\axiax\Desktop\hakaton\users\models.py changed, reloading.
INFO:django.utils.autoreload:C:\Users\axiax\Desktop\hakaton\users\views.py changed, reloading.
ERROR:django.request:Internal Server Error: /
Traceback (most recent call last):
  File "C:\Users\axiax\AppData\Local\Programs\Python\Python38\lib\site-packages\django\core\handlers\exception.py", line 47, in inner
    response = get_response(request)
  File "C:\Users\axiax\AppData\Local\Programs\Python\Python38\lib\site-packages\django\core\handlers\base.py", line 181, in _get_response
    response = wrapped_callback(request, *callback_args, **callback_kwargs)
  File "C:\Users\axiax\AppData\Local\Programs\Python\Python38\lib\site-packages\django\views\generic\base.py", line 70, in view
    return self.dispatch(request, *args, **kwargs)
  File "C:\Users\axiax\AppData\Local\Programs\Python\Python38\lib\site-packages\django\views\generic\base.py", line 98, in dispatch
    return handler(request, *args, **kwargs)
  File "C:\Users\axiax\AppData\Local\Programs\Python\Python38\lib\site-packages\django\views\generic\edit.py", line 142, in post
    return self.form_valid(form)
  File "C:\Users\axiax\Desktop\hakaton\users\views.py", line 53, in form_valid
    self.get_context_data(phone=self.phone)
AttributeError: 'AuthView' object has no attribute 'phone'
INFO:django.utils.autoreload:C:\Users\axiax\Desktop\hakaton\users\views.py changed, reloading.
ERROR:django.request:Internal Server Error: /
Traceback (most recent call last):
  File "C:\Users\axiax\AppData\Local\Programs\Python\Python38\lib\site-packages\django\urls\base.py", line 71, in reverse
    extra, resolver = resolver.namespace_dict[ns]
KeyError: 'users'

During handling of the above exception, another exception occurred:

Traceback (most recent call last):
  File "C:\Users\axiax\AppData\Local\Programs\Python\Python38\lib\site-packages\django\core\handlers\exception.py", line 47, in inner
    response = get_response(request)
  File "C:\Users\axiax\AppData\Local\Programs\Python\Python38\lib\site-packages\django\core\handlers\base.py", line 181, in _get_response
    response = wrapped_callback(request, *callback_args, **callback_kwargs)
  File "C:\Users\axiax\AppData\Local\Programs\Python\Python38\lib\site-packages\django\views\generic\base.py", line 70, in view
    return self.dispatch(request, *args, **kwargs)
  File "C:\Users\axiax\AppData\Local\Programs\Python\Python38\lib\site-packages\django\views\generic\base.py", line 98, in dispatch
    return handler(request, *args, **kwargs)
  File "C:\Users\axiax\AppData\Local\Programs\Python\Python38\lib\site-packages\django\views\generic\edit.py", line 142, in post
    return self.form_valid(form)
  File "C:\Users\axiax\Desktop\hakaton\users\views.py", line 55, in form_valid
    response['Location'] = reverse('users:cpanel')
  File "C:\Users\axiax\AppData\Local\Programs\Python\Python38\lib\site-packages\django\urls\base.py", line 82, in reverse
    raise NoReverseMatch("%s is not a registered namespace" % key)
django.urls.exceptions.NoReverseMatch: 'users' is not a registered namespace
INFO:django.utils.autoreload:C:\Users\axiax\Desktop\hakaton\users\views.py changed, reloading.
INFO:django.utils.autoreload:C:\Users\axiax\Desktop\hakaton\users\views.py changed, reloading.
INFO:django.utils.autoreload:C:\Users\axiax\Desktop\hakaton\users\views.py changed, reloading.
ERROR:django.request:Internal Server Error: /
Traceback (most recent call last):
  File "C:\Users\axiax\AppData\Local\Programs\Python\Python38\lib\site-packages\django\core\handlers\exception.py", line 47, in inner
    response = get_response(request)
  File "C:\Users\axiax\AppData\Local\Programs\Python\Python38\lib\site-packages\django\core\handlers\base.py", line 188, in _get_response
    self.check_response(response, callback)
  File "C:\Users\axiax\AppData\Local\Programs\Python\Python38\lib\site-packages\django\core\handlers\base.py", line 309, in check_response
    raise ValueError(
ValueError: The view users.views.AuthView didn't return an HttpResponse object. It returned None instead.
INFO:django.utils.autoreload:C:\Users\axiax\Desktop\hakaton\users\views.py changed, reloading.
ERROR:django.request:Internal Server Error: /
Traceback (most recent call last):
  File "C:\Users\axiax\AppData\Local\Programs\Python\Python38\lib\site-packages\django\core\handlers\exception.py", line 47, in inner
    response = get_response(request)
  File "C:\Users\axiax\AppData\Local\Programs\Python\Python38\lib\site-packages\django\core\handlers\base.py", line 181, in _get_response
    response = wrapped_callback(request, *callback_args, **callback_kwargs)
  File "C:\Users\axiax\AppData\Local\Programs\Python\Python38\lib\site-packages\django\views\generic\base.py", line 70, in view
    return self.dispatch(request, *args, **kwargs)
  File "C:\Users\axiax\AppData\Local\Programs\Python\Python38\lib\site-packages\django\views\generic\base.py", line 98, in dispatch
    return handler(request, *args, **kwargs)
  File "C:\Users\axiax\Desktop\hakaton\users\views.py", line 36, in post
    user = User.objects.create(username=phone, email=self.email)
NameError: name 'phone' is not defined
INFO:django.utils.autoreload:C:\Users\axiax\Desktop\hakaton\users\views.py changed, reloading.
ERROR:django.request:Internal Server Error: /
Traceback (most recent call last):
  File "C:\Users\axiax\AppData\Local\Programs\Python\Python38\lib\site-packages\django\core\handlers\exception.py", line 47, in inner
    response = get_response(request)
  File "C:\Users\axiax\AppData\Local\Programs\Python\Python38\lib\site-packages\django\core\handlers\base.py", line 181, in _get_response
    response = wrapped_callback(request, *callback_args, **callback_kwargs)
  File "C:\Users\axiax\AppData\Local\Programs\Python\Python38\lib\site-packages\django\views\generic\base.py", line 70, in view
    return self.dispatch(request, *args, **kwargs)
  File "C:\Users\axiax\AppData\Local\Programs\Python\Python38\lib\site-packages\django\views\generic\base.py", line 98, in dispatch
    return handler(request, *args, **kwargs)
  File "C:\Users\axiax\Desktop\hakaton\users\views.py", line 36, in post
    user = User.objects.create(username=self.phone, email=self.email)
AttributeError: 'AuthView' object has no attribute 'phone'
INFO:django.utils.autoreload:C:\Users\axiax\Desktop\hakaton\users\views.py changed, reloading.
ERROR:django.request:Internal Server Error: /
Traceback (most recent call last):
  File "C:\Users\axiax\AppData\Local\Programs\Python\Python38\lib\site-packages\django\core\handlers\exception.py", line 47, in inner
    response = get_response(request)
  File "C:\Users\axiax\AppData\Local\Programs\Python\Python38\lib\site-packages\django\core\handlers\base.py", line 188, in _get_response
    self.check_response(response, callback)
  File "C:\Users\axiax\AppData\Local\Programs\Python\Python38\lib\site-packages\django\core\handlers\base.py", line 309, in check_response
    raise ValueError(
ValueError: The view users.views.AuthView didn't return an HttpResponse object. It returned None instead.
INFO:django.utils.autoreload:C:\Users\axiax\Desktop\hakaton\users\views.py changed, reloading.
